[2025-02-13T06:41:35.676+0000] {local_task_job_runner.py:123} INFO - ::group::Pre task execution logs
[2025-02-13T06:41:35.728+0000] {taskinstance.py:2614} INFO - Dependencies all met for dep_context=non-requeueable deps ti=<TaskInstance: sec_data_pipeline.download_zip manual__2025-02-13T06:36:22.718839+00:00 [queued]>
[2025-02-13T06:41:35.755+0000] {taskinstance.py:2614} INFO - Dependencies all met for dep_context=requeueable deps ti=<TaskInstance: sec_data_pipeline.download_zip manual__2025-02-13T06:36:22.718839+00:00 [queued]>
[2025-02-13T06:41:35.756+0000] {taskinstance.py:2867} INFO - Starting attempt 2 of 2
[2025-02-13T06:41:35.778+0000] {taskinstance.py:2890} INFO - Executing <Task(PythonOperator): download_zip> on 2025-02-13 06:36:22.718839+00:00
[2025-02-13T06:41:35.790+0000] {warnings.py:112} WARNING - /home/***/.local/lib/python3.12/site-packages/***/task/task_runner/standard_task_runner.py:70: DeprecationWarning: This process (pid=109) is multi-threaded, use of fork() may lead to deadlocks in the child.
  pid = os.fork()

[2025-02-13T06:41:35.792+0000] {standard_task_runner.py:104} INFO - Running: ['***', 'tasks', 'run', 'sec_data_pipeline', 'download_zip', 'manual__2025-02-13T06:36:22.718839+00:00', '--job-id', '22', '--raw', '--subdir', 'DAGS_FOLDER/webscrape.py', '--cfg-path', '/tmp/tmp913m8xy2']
[2025-02-13T06:41:35.794+0000] {standard_task_runner.py:72} INFO - Started process 110 to run task
[2025-02-13T06:41:35.794+0000] {standard_task_runner.py:105} INFO - Job 22: Subtask download_zip
[2025-02-13T06:41:35.874+0000] {task_command.py:467} INFO - Running <TaskInstance: sec_data_pipeline.download_zip manual__2025-02-13T06:36:22.718839+00:00 [running]> on host 8857fc08f6e4
[2025-02-13T06:41:36.022+0000] {taskinstance.py:3134} INFO - Exporting env vars: AIRFLOW_CTX_DAG_OWNER='***' AIRFLOW_CTX_DAG_ID='sec_data_pipeline' AIRFLOW_CTX_TASK_ID='download_zip' AIRFLOW_CTX_EXECUTION_DATE='2025-02-13T06:36:22.718839+00:00' AIRFLOW_CTX_TRY_NUMBER='2' AIRFLOW_CTX_DAG_RUN_ID='manual__2025-02-13T06:36:22.718839+00:00'
[2025-02-13T06:41:36.025+0000] {taskinstance.py:732} INFO - ::endgroup::
[2025-02-13T06:41:36.074+0000] {logger.py:11} INFO - ====== WebDriver manager ======
[2025-02-13T06:41:36.471+0000] {logger.py:11} INFO - Get LATEST chromedriver version for google-chrome
[2025-02-13T06:41:36.711+0000] {logger.py:11} INFO - Get LATEST chromedriver version for google-chrome
[2025-02-13T06:41:36.804+0000] {logger.py:11} INFO - Driver [/home/***/.wdm/drivers/chromedriver/linux64/133.0.6943.98/chromedriver-linux64/chromedriver] found in cache
[2025-02-13T06:41:37.179+0000] {taskinstance.py:3313} ERROR - Task failed with exception
Traceback (most recent call last):
  File "/home/airflow/.local/lib/python3.12/site-packages/airflow/models/taskinstance.py", line 768, in _execute_task
    result = _execute_callable(context=context, **execute_callable_kwargs)
             ^^^^^^^^^^^^^^^^^^^^^^^^^^^^^^^^^^^^^^^^^^^^^^^^^^^^^^^^^^^^^
  File "/home/airflow/.local/lib/python3.12/site-packages/airflow/models/taskinstance.py", line 734, in _execute_callable
    return ExecutionCallableRunner(
           ^^^^^^^^^^^^^^^^^^^^^^^^
  File "/home/airflow/.local/lib/python3.12/site-packages/airflow/utils/operator_helpers.py", line 252, in run
    return self.func(*args, **kwargs)
           ^^^^^^^^^^^^^^^^^^^^^^^^^^
  File "/home/airflow/.local/lib/python3.12/site-packages/airflow/models/baseoperator.py", line 424, in wrapper
    return func(self, *args, **kwargs)
           ^^^^^^^^^^^^^^^^^^^^^^^^^^^
  File "/home/airflow/.local/lib/python3.12/site-packages/airflow/operators/python.py", line 238, in execute
    return_value = self.execute_callable()
                   ^^^^^^^^^^^^^^^^^^^^^^^
  File "/home/airflow/.local/lib/python3.12/site-packages/airflow/operators/python.py", line 256, in execute_callable
    return runner.run(*self.op_args, **self.op_kwargs)
           ^^^^^^^^^^^^^^^^^^^^^^^^^^^^^^^^^^^^^^^^^^^
  File "/home/airflow/.local/lib/python3.12/site-packages/airflow/utils/operator_helpers.py", line 252, in run
    return self.func(*args, **kwargs)
           ^^^^^^^^^^^^^^^^^^^^^^^^^^
  File "/opt/airflow/dags/webscrape.py", line 53, in download_with_selenium
    driver = webdriver.Chrome(service=Service(ChromeDriverManager().install()), options=options)
             ^^^^^^^^^^^^^^^^^^^^^^^^^^^^^^^^^^^^^^^^^^^^^^^^^^^^^^^^^^^^^^^^^^^^^^^^^^^^^^^^^^^
  File "/home/airflow/.local/lib/python3.12/site-packages/selenium/webdriver/chrome/webdriver.py", line 45, in __init__
    super().__init__(
  File "/home/airflow/.local/lib/python3.12/site-packages/selenium/webdriver/chromium/webdriver.py", line 66, in __init__
    super().__init__(command_executor=executor, options=options)
  File "/home/airflow/.local/lib/python3.12/site-packages/selenium/webdriver/remote/webdriver.py", line 250, in __init__
    self.start_session(capabilities)
  File "/home/airflow/.local/lib/python3.12/site-packages/selenium/webdriver/remote/webdriver.py", line 342, in start_session
    response = self.execute(Command.NEW_SESSION, caps)["value"]
               ^^^^^^^^^^^^^^^^^^^^^^^^^^^^^^^^^^^^^^^
  File "/home/airflow/.local/lib/python3.12/site-packages/selenium/webdriver/remote/webdriver.py", line 429, in execute
    self.error_handler.check_response(response)
  File "/home/airflow/.local/lib/python3.12/site-packages/selenium/webdriver/remote/errorhandler.py", line 232, in check_response
    raise exception_class(message, screen, stacktrace)
selenium.common.exceptions.SessionNotCreatedException: Message: session not created: probably user data directory is already in use, please specify a unique value for --user-data-dir argument, or don't use --user-data-dir
Stacktrace:
#0 0x5599be369bba <unknown>
#1 0x5599bde07790 <unknown>
#2 0x5599bde40bc5 <unknown>
#3 0x5599bde3c92f <unknown>
#4 0x5599bde8d369 <unknown>
#5 0x5599bde8c896 <unknown>
#6 0x5599bde7e823 <unknown>
#7 0x5599bde4aa88 <unknown>
#8 0x5599bde4bbf1 <unknown>
#9 0x5599be33315b <unknown>
#10 0x5599be3370e2 <unknown>
#11 0x5599be32001c <unknown>
#12 0x5599be337cd4 <unknown>
#13 0x5599be30448f <unknown>
#14 0x5599be3584f8 <unknown>
#15 0x5599be3586c9 <unknown>
#16 0x5599be368a36 <unknown>
#17 0x7fe5c098f1c4 <unknown>

[2025-02-13T06:41:37.202+0000] {taskinstance.py:1226} INFO - Marking task as FAILED. dag_id=sec_data_pipeline, task_id=download_zip, run_id=manual__2025-02-13T06:36:22.718839+00:00, execution_date=20250213T063622, start_date=20250213T064135, end_date=20250213T064137
[2025-02-13T06:41:37.241+0000] {taskinstance.py:341} INFO - ::group::Post task execution logs
[2025-02-13T06:41:37.242+0000] {standard_task_runner.py:124} ERROR - Failed to execute job 22 for task download_zip (Message: session not created: probably user data directory is already in use, please specify a unique value for --user-data-dir argument, or don't use --user-data-dir
Stacktrace:
#0 0x5599be369bba <unknown>
#1 0x5599bde07790 <unknown>
#2 0x5599bde40bc5 <unknown>
#3 0x5599bde3c92f <unknown>
#4 0x5599bde8d369 <unknown>
#5 0x5599bde8c896 <unknown>
#6 0x5599bde7e823 <unknown>
#7 0x5599bde4aa88 <unknown>
#8 0x5599bde4bbf1 <unknown>
#9 0x5599be33315b <unknown>
#10 0x5599be3370e2 <unknown>
#11 0x5599be32001c <unknown>
#12 0x5599be337cd4 <unknown>
#13 0x5599be30448f <unknown>
#14 0x5599be3584f8 <unknown>
#15 0x5599be3586c9 <unknown>
#16 0x5599be368a36 <unknown>
#17 0x7fe5c098f1c4 <unknown>
; 110)
Traceback (most recent call last):
  File "/home/airflow/.local/lib/python3.12/site-packages/airflow/task/task_runner/standard_task_runner.py", line 117, in _start_by_fork
    ret = args.func(args, dag=self.dag)
          ^^^^^^^^^^^^^^^^^^^^^^^^^^^^^
  File "/home/airflow/.local/lib/python3.12/site-packages/airflow/cli/cli_config.py", line 49, in command
    return func(*args, **kwargs)
           ^^^^^^^^^^^^^^^^^^^^^
  File "/home/airflow/.local/lib/python3.12/site-packages/airflow/utils/cli.py", line 116, in wrapper
    return f(*args, **kwargs)
           ^^^^^^^^^^^^^^^^^^
  File "/home/airflow/.local/lib/python3.12/site-packages/airflow/cli/commands/task_command.py", line 483, in task_run
    task_return_code = _run_task_by_selected_method(args, _dag, ti)
                       ^^^^^^^^^^^^^^^^^^^^^^^^^^^^^^^^^^^^^^^^^^^^
  File "/home/airflow/.local/lib/python3.12/site-packages/airflow/cli/commands/task_command.py", line 256, in _run_task_by_selected_method
    return _run_raw_task(args, ti)
           ^^^^^^^^^^^^^^^^^^^^^^^
  File "/home/airflow/.local/lib/python3.12/site-packages/airflow/cli/commands/task_command.py", line 341, in _run_raw_task
    return ti._run_raw_task(
           ^^^^^^^^^^^^^^^^^
  File "/home/airflow/.local/lib/python3.12/site-packages/airflow/utils/session.py", line 97, in wrapper
    return func(*args, session=session, **kwargs)
           ^^^^^^^^^^^^^^^^^^^^^^^^^^^^^^^^^^^^^^
  File "/home/airflow/.local/lib/python3.12/site-packages/airflow/models/taskinstance.py", line 3006, in _run_raw_task
    return _run_raw_task(
           ^^^^^^^^^^^^^^
  File "/home/airflow/.local/lib/python3.12/site-packages/airflow/models/taskinstance.py", line 274, in _run_raw_task
    TaskInstance._execute_task_with_callbacks(
  File "/home/airflow/.local/lib/python3.12/site-packages/airflow/models/taskinstance.py", line 3161, in _execute_task_with_callbacks
    result = self._execute_task(context, task_orig)
             ^^^^^^^^^^^^^^^^^^^^^^^^^^^^^^^^^^^^^^
  File "/home/airflow/.local/lib/python3.12/site-packages/airflow/models/taskinstance.py", line 3185, in _execute_task
    return _execute_task(self, context, task_orig)
           ^^^^^^^^^^^^^^^^^^^^^^^^^^^^^^^^^^^^^^^
  File "/home/airflow/.local/lib/python3.12/site-packages/airflow/models/taskinstance.py", line 768, in _execute_task
    result = _execute_callable(context=context, **execute_callable_kwargs)
             ^^^^^^^^^^^^^^^^^^^^^^^^^^^^^^^^^^^^^^^^^^^^^^^^^^^^^^^^^^^^^
  File "/home/airflow/.local/lib/python3.12/site-packages/airflow/models/taskinstance.py", line 734, in _execute_callable
    return ExecutionCallableRunner(
           ^^^^^^^^^^^^^^^^^^^^^^^^
  File "/home/airflow/.local/lib/python3.12/site-packages/airflow/utils/operator_helpers.py", line 252, in run
    return self.func(*args, **kwargs)
           ^^^^^^^^^^^^^^^^^^^^^^^^^^
  File "/home/airflow/.local/lib/python3.12/site-packages/airflow/models/baseoperator.py", line 424, in wrapper
    return func(self, *args, **kwargs)
           ^^^^^^^^^^^^^^^^^^^^^^^^^^^
  File "/home/airflow/.local/lib/python3.12/site-packages/airflow/operators/python.py", line 238, in execute
    return_value = self.execute_callable()
                   ^^^^^^^^^^^^^^^^^^^^^^^
  File "/home/airflow/.local/lib/python3.12/site-packages/airflow/operators/python.py", line 256, in execute_callable
    return runner.run(*self.op_args, **self.op_kwargs)
           ^^^^^^^^^^^^^^^^^^^^^^^^^^^^^^^^^^^^^^^^^^^
  File "/home/airflow/.local/lib/python3.12/site-packages/airflow/utils/operator_helpers.py", line 252, in run
    return self.func(*args, **kwargs)
           ^^^^^^^^^^^^^^^^^^^^^^^^^^
  File "/opt/airflow/dags/webscrape.py", line 53, in download_with_selenium
    driver = webdriver.Chrome(service=Service(ChromeDriverManager().install()), options=options)
             ^^^^^^^^^^^^^^^^^^^^^^^^^^^^^^^^^^^^^^^^^^^^^^^^^^^^^^^^^^^^^^^^^^^^^^^^^^^^^^^^^^^
  File "/home/airflow/.local/lib/python3.12/site-packages/selenium/webdriver/chrome/webdriver.py", line 45, in __init__
    super().__init__(
  File "/home/airflow/.local/lib/python3.12/site-packages/selenium/webdriver/chromium/webdriver.py", line 66, in __init__
    super().__init__(command_executor=executor, options=options)
  File "/home/airflow/.local/lib/python3.12/site-packages/selenium/webdriver/remote/webdriver.py", line 250, in __init__
    self.start_session(capabilities)
  File "/home/airflow/.local/lib/python3.12/site-packages/selenium/webdriver/remote/webdriver.py", line 342, in start_session
    response = self.execute(Command.NEW_SESSION, caps)["value"]
               ^^^^^^^^^^^^^^^^^^^^^^^^^^^^^^^^^^^^^^^
  File "/home/airflow/.local/lib/python3.12/site-packages/selenium/webdriver/remote/webdriver.py", line 429, in execute
    self.error_handler.check_response(response)
  File "/home/airflow/.local/lib/python3.12/site-packages/selenium/webdriver/remote/errorhandler.py", line 232, in check_response
    raise exception_class(message, screen, stacktrace)
selenium.common.exceptions.SessionNotCreatedException: Message: session not created: probably user data directory is already in use, please specify a unique value for --user-data-dir argument, or don't use --user-data-dir
Stacktrace:
#0 0x5599be369bba <unknown>
#1 0x5599bde07790 <unknown>
#2 0x5599bde40bc5 <unknown>
#3 0x5599bde3c92f <unknown>
#4 0x5599bde8d369 <unknown>
#5 0x5599bde8c896 <unknown>
#6 0x5599bde7e823 <unknown>
#7 0x5599bde4aa88 <unknown>
#8 0x5599bde4bbf1 <unknown>
#9 0x5599be33315b <unknown>
#10 0x5599be3370e2 <unknown>
#11 0x5599be32001c <unknown>
#12 0x5599be337cd4 <unknown>
#13 0x5599be30448f <unknown>
#14 0x5599be3584f8 <unknown>
#15 0x5599be3586c9 <unknown>
#16 0x5599be368a36 <unknown>
#17 0x7fe5c098f1c4 <unknown>

[2025-02-13T06:41:37.301+0000] {local_task_job_runner.py:266} INFO - Task exited with return code 1
[2025-02-13T06:41:37.339+0000] {taskinstance.py:3901} INFO - 0 downstream tasks scheduled from follow-on schedule check
[2025-02-13T06:41:37.345+0000] {local_task_job_runner.py:245} INFO - ::endgroup::
