[2025-02-14T18:55:40.629+0000] {local_task_job_runner.py:123} INFO - ::group::Pre task execution logs
[2025-02-14T18:55:40.659+0000] {taskinstance.py:2614} INFO - Dependencies all met for dep_context=non-requeueable deps ti=<TaskInstance: dbt_data_pipeline.install_dbt_dependencies manual__2025-02-14T18:55:38.773511+00:00 [queued]>
[2025-02-14T18:55:40.673+0000] {taskinstance.py:2614} INFO - Dependencies all met for dep_context=requeueable deps ti=<TaskInstance: dbt_data_pipeline.install_dbt_dependencies manual__2025-02-14T18:55:38.773511+00:00 [queued]>
[2025-02-14T18:55:40.674+0000] {taskinstance.py:2867} INFO - Starting attempt 1 of 2
[2025-02-14T18:55:40.697+0000] {taskinstance.py:2890} INFO - Executing <Task(BashOperator): install_dbt_dependencies> on 2025-02-14 18:55:38.773511+00:00
[2025-02-14T18:55:40.705+0000] {warnings.py:112} WARNING - /home/***/.local/lib/python3.12/site-packages/***/task/task_runner/standard_task_runner.py:70: DeprecationWarning: This process (pid=52) is multi-threaded, use of fork() may lead to deadlocks in the child.
  pid = os.fork()

[2025-02-14T18:55:40.707+0000] {standard_task_runner.py:104} INFO - Running: ['***', 'tasks', 'run', 'dbt_data_pipeline', 'install_dbt_dependencies', 'manual__2025-02-14T18:55:38.773511+00:00', '--job-id', '137', '--raw', '--subdir', 'DAGS_FOLDER/dbt-chck.py', '--cfg-path', '/tmp/tmppqj8exkh']
[2025-02-14T18:55:40.708+0000] {standard_task_runner.py:72} INFO - Started process 53 to run task
[2025-02-14T18:55:40.709+0000] {standard_task_runner.py:105} INFO - Job 137: Subtask install_dbt_dependencies
[2025-02-14T18:55:40.789+0000] {task_command.py:467} INFO - Running <TaskInstance: dbt_data_pipeline.install_dbt_dependencies manual__2025-02-14T18:55:38.773511+00:00 [running]> on host bfc488d26d32
[2025-02-14T18:55:40.898+0000] {taskinstance.py:3134} INFO - Exporting env vars: AIRFLOW_CTX_DAG_OWNER='***' AIRFLOW_CTX_DAG_ID='dbt_data_pipeline' AIRFLOW_CTX_TASK_ID='install_dbt_dependencies' AIRFLOW_CTX_EXECUTION_DATE='2025-02-14T18:55:38.773511+00:00' AIRFLOW_CTX_TRY_NUMBER='1' AIRFLOW_CTX_DAG_RUN_ID='manual__2025-02-14T18:55:38.773511+00:00'
[2025-02-14T18:55:40.900+0000] {taskinstance.py:732} INFO - ::endgroup::
[2025-02-14T18:55:40.919+0000] {subprocess.py:78} INFO - Tmp dir root location: /tmp
[2025-02-14T18:55:40.921+0000] {subprocess.py:88} INFO - Running command: ['/usr/bin/bash', '-c', 'cd /opt/***/dbt/data_pipeline && dbt deps']
[2025-02-14T18:55:40.935+0000] {subprocess.py:99} INFO - Output:
[2025-02-14T18:55:40.941+0000] {subprocess.py:106} INFO - /usr/bin/bash: line 1: dbt: command not found
[2025-02-14T18:55:40.942+0000] {subprocess.py:110} INFO - Command exited with return code 127
[2025-02-14T18:55:40.956+0000] {taskinstance.py:3313} ERROR - Task failed with exception
Traceback (most recent call last):
  File "/home/airflow/.local/lib/python3.12/site-packages/airflow/models/taskinstance.py", line 768, in _execute_task
    result = _execute_callable(context=context, **execute_callable_kwargs)
             ^^^^^^^^^^^^^^^^^^^^^^^^^^^^^^^^^^^^^^^^^^^^^^^^^^^^^^^^^^^^^
  File "/home/airflow/.local/lib/python3.12/site-packages/airflow/models/taskinstance.py", line 734, in _execute_callable
    return ExecutionCallableRunner(
           ^^^^^^^^^^^^^^^^^^^^^^^^
  File "/home/airflow/.local/lib/python3.12/site-packages/airflow/utils/operator_helpers.py", line 252, in run
    return self.func(*args, **kwargs)
           ^^^^^^^^^^^^^^^^^^^^^^^^^^
  File "/home/airflow/.local/lib/python3.12/site-packages/airflow/models/baseoperator.py", line 424, in wrapper
    return func(self, *args, **kwargs)
           ^^^^^^^^^^^^^^^^^^^^^^^^^^^
  File "/home/airflow/.local/lib/python3.12/site-packages/airflow/operators/bash.py", line 276, in execute
    raise AirflowException(
airflow.exceptions.AirflowException: Bash command failed. The command returned a non-zero exit code 127.
[2025-02-14T18:55:40.968+0000] {taskinstance.py:1226} INFO - Marking task as UP_FOR_RETRY. dag_id=dbt_data_pipeline, task_id=install_dbt_dependencies, run_id=manual__2025-02-14T18:55:38.773511+00:00, execution_date=20250214T185538, start_date=20250214T185540, end_date=20250214T185540
[2025-02-14T18:55:41.008+0000] {taskinstance.py:341} INFO - ::group::Post task execution logs
[2025-02-14T18:55:41.009+0000] {standard_task_runner.py:124} ERROR - Failed to execute job 137 for task install_dbt_dependencies (Bash command failed. The command returned a non-zero exit code 127.; 53)
Traceback (most recent call last):
  File "/home/airflow/.local/lib/python3.12/site-packages/airflow/task/task_runner/standard_task_runner.py", line 117, in _start_by_fork
    ret = args.func(args, dag=self.dag)
          ^^^^^^^^^^^^^^^^^^^^^^^^^^^^^
  File "/home/airflow/.local/lib/python3.12/site-packages/airflow/cli/cli_config.py", line 49, in command
    return func(*args, **kwargs)
           ^^^^^^^^^^^^^^^^^^^^^
  File "/home/airflow/.local/lib/python3.12/site-packages/airflow/utils/cli.py", line 116, in wrapper
    return f(*args, **kwargs)
           ^^^^^^^^^^^^^^^^^^
  File "/home/airflow/.local/lib/python3.12/site-packages/airflow/cli/commands/task_command.py", line 483, in task_run
    task_return_code = _run_task_by_selected_method(args, _dag, ti)
                       ^^^^^^^^^^^^^^^^^^^^^^^^^^^^^^^^^^^^^^^^^^^^
  File "/home/airflow/.local/lib/python3.12/site-packages/airflow/cli/commands/task_command.py", line 256, in _run_task_by_selected_method
    return _run_raw_task(args, ti)
           ^^^^^^^^^^^^^^^^^^^^^^^
  File "/home/airflow/.local/lib/python3.12/site-packages/airflow/cli/commands/task_command.py", line 341, in _run_raw_task
    return ti._run_raw_task(
           ^^^^^^^^^^^^^^^^^
  File "/home/airflow/.local/lib/python3.12/site-packages/airflow/utils/session.py", line 97, in wrapper
    return func(*args, session=session, **kwargs)
           ^^^^^^^^^^^^^^^^^^^^^^^^^^^^^^^^^^^^^^
  File "/home/airflow/.local/lib/python3.12/site-packages/airflow/models/taskinstance.py", line 3006, in _run_raw_task
    return _run_raw_task(
           ^^^^^^^^^^^^^^
  File "/home/airflow/.local/lib/python3.12/site-packages/airflow/models/taskinstance.py", line 274, in _run_raw_task
    TaskInstance._execute_task_with_callbacks(
  File "/home/airflow/.local/lib/python3.12/site-packages/airflow/models/taskinstance.py", line 3161, in _execute_task_with_callbacks
    result = self._execute_task(context, task_orig)
             ^^^^^^^^^^^^^^^^^^^^^^^^^^^^^^^^^^^^^^
  File "/home/airflow/.local/lib/python3.12/site-packages/airflow/models/taskinstance.py", line 3185, in _execute_task
    return _execute_task(self, context, task_orig)
           ^^^^^^^^^^^^^^^^^^^^^^^^^^^^^^^^^^^^^^^
  File "/home/airflow/.local/lib/python3.12/site-packages/airflow/models/taskinstance.py", line 768, in _execute_task
    result = _execute_callable(context=context, **execute_callable_kwargs)
             ^^^^^^^^^^^^^^^^^^^^^^^^^^^^^^^^^^^^^^^^^^^^^^^^^^^^^^^^^^^^^
  File "/home/airflow/.local/lib/python3.12/site-packages/airflow/models/taskinstance.py", line 734, in _execute_callable
    return ExecutionCallableRunner(
           ^^^^^^^^^^^^^^^^^^^^^^^^
  File "/home/airflow/.local/lib/python3.12/site-packages/airflow/utils/operator_helpers.py", line 252, in run
    return self.func(*args, **kwargs)
           ^^^^^^^^^^^^^^^^^^^^^^^^^^
  File "/home/airflow/.local/lib/python3.12/site-packages/airflow/models/baseoperator.py", line 424, in wrapper
    return func(self, *args, **kwargs)
           ^^^^^^^^^^^^^^^^^^^^^^^^^^^
  File "/home/airflow/.local/lib/python3.12/site-packages/airflow/operators/bash.py", line 276, in execute
    raise AirflowException(
airflow.exceptions.AirflowException: Bash command failed. The command returned a non-zero exit code 127.
[2025-02-14T18:55:41.047+0000] {local_task_job_runner.py:266} INFO - Task exited with return code 1
[2025-02-14T18:55:41.077+0000] {taskinstance.py:3901} INFO - 0 downstream tasks scheduled from follow-on schedule check
[2025-02-14T18:55:41.081+0000] {local_task_job_runner.py:245} INFO - ::endgroup::
