[2025-02-14T10:04:26.141+0000] {local_task_job_runner.py:123} INFO - ::group::Pre task execution logs
[2025-02-14T10:04:26.224+0000] {taskinstance.py:2614} INFO - Dependencies all met for dep_context=non-requeueable deps ti=<TaskInstance: check_all_snowflake_tables.check_tables_existence manual__2025-02-14T10:04:19.180713+00:00 [queued]>
[2025-02-14T10:04:26.247+0000] {taskinstance.py:2614} INFO - Dependencies all met for dep_context=requeueable deps ti=<TaskInstance: check_all_snowflake_tables.check_tables_existence manual__2025-02-14T10:04:19.180713+00:00 [queued]>
[2025-02-14T10:04:26.249+0000] {taskinstance.py:2867} INFO - Starting attempt 1 of 1
[2025-02-14T10:04:26.292+0000] {taskinstance.py:2890} INFO - Executing <Task(SnowflakeOperator): check_tables_existence> on 2025-02-14 10:04:19.180713+00:00
[2025-02-14T10:04:26.321+0000] {warnings.py:112} WARNING - /home/***/.local/lib/python3.12/site-packages/***/task/task_runner/standard_task_runner.py:70: DeprecationWarning: This process (pid=57) is multi-threaded, use of fork() may lead to deadlocks in the child.
  pid = os.fork()

[2025-02-14T10:04:26.330+0000] {standard_task_runner.py:72} INFO - Started process 59 to run task
[2025-02-14T10:04:26.332+0000] {standard_task_runner.py:104} INFO - Running: ['***', 'tasks', 'run', 'check_all_snowflake_tables', 'check_tables_existence', 'manual__2025-02-14T10:04:19.180713+00:00', '--job-id', '67', '--raw', '--subdir', 'DAGS_FOLDER/snow.py', '--cfg-path', '/tmp/tmpz2qdhrhh']
[2025-02-14T10:04:26.341+0000] {standard_task_runner.py:105} INFO - Job 67: Subtask check_tables_existence
[2025-02-14T10:04:26.612+0000] {task_command.py:467} INFO - Running <TaskInstance: check_all_snowflake_tables.check_tables_existence manual__2025-02-14T10:04:19.180713+00:00 [running]> on host 94016f1f831c
[2025-02-14T10:04:26.883+0000] {taskinstance.py:3134} INFO - Exporting env vars: AIRFLOW_CTX_DAG_OWNER='***' AIRFLOW_CTX_DAG_ID='check_all_snowflake_tables' AIRFLOW_CTX_TASK_ID='check_tables_existence' AIRFLOW_CTX_EXECUTION_DATE='2025-02-14T10:04:19.180713+00:00' AIRFLOW_CTX_TRY_NUMBER='1' AIRFLOW_CTX_DAG_RUN_ID='manual__2025-02-14T10:04:19.180713+00:00'
[2025-02-14T10:04:26.893+0000] {taskinstance.py:732} INFO - ::endgroup::
[2025-02-14T10:04:26.939+0000] {sql.py:295} INFO - Executing: 
SELECT COUNT(*) AS table_count FROM INFORMATION_SCHEMA.TABLES 
WHERE TABLE_NAME IN ('num', 'pre', 'tag', 'raw_sub') 
AND TABLE_SCHEMA = 'dbt_schema' AND TABLE_CATALOG = 'dbt_db';
[2025-02-14T10:04:26.994+0000] {base.py:84} INFO - Retrieving connection 'snowflake_default'
[2025-02-14T10:04:27.027+0000] {base.py:84} INFO - Retrieving connection 'snowflake_default'
[2025-02-14T10:04:27.034+0000] {connection.py:424} INFO - Snowflake Connector for Python Version: 3.13.2, Python Version: 3.12.9, Platform: Linux-5.15.133.1-microsoft-standard-WSL2-x86_64-with-glibc2.36
[2025-02-14T10:04:27.037+0000] {connection.py:1213} INFO - Connecting to GLOBAL Snowflake domain
[2025-02-14T10:04:27.040+0000] {connection.py:1295} INFO - This connection is in OCSP Fail Open Mode. TLS Certificates would be checked for validity and revocation status. Any other Certificate Revocation related exceptions or OCSP Responder failures would be disregarded in favor of connectivity.
[2025-02-14T10:04:27.063+0000] {connectionpool.py:824} WARNING - Retrying (Retry(total=0, connect=None, read=None, redirect=None, status=None)) after connection broken by 'NewConnectionError('<snowflake.connector.vendored.urllib3.connection.HTTPSConnection object at 0x7fdf59dbb590>: Failed to establish a new connection: [Errno -2] Name or service not known')': /session/v1/login-request?request_id=7814ed98-ec9c-4a97-9fcd-b03e5e5f60c0&databaseName=dbt_db&schemaName=dbt_schema&warehouse=dbt_wh&roleName=dbt_role&request_guid=238da89b-9952-4013-a89f-2685c7e015ed
[2025-02-14T10:04:28.108+0000] {connectionpool.py:824} WARNING - Retrying (Retry(total=0, connect=None, read=None, redirect=None, status=None)) after connection broken by 'NewConnectionError('<snowflake.connector.vendored.urllib3.connection.HTTPSConnection object at 0x7fdf44cd3fb0>: Failed to establish a new connection: [Errno -2] Name or service not known')': /session/v1/login-request?request_id=b52064d7-0673-4a1a-b446-79fc3c11d7c1&databaseName=dbt_db&schemaName=dbt_schema&warehouse=dbt_wh&roleName=dbt_role&request_guid=43fff60f-adae-4705-8c58-2563cfe1dc7e
[2025-02-14T10:04:28.119+0000] {taskinstance.py:3313} ERROR - Task failed with exception
Traceback (most recent call last):
  File "/home/airflow/.local/lib/python3.12/site-packages/snowflake/connector/vendored/urllib3/connection.py", line 174, in _new_conn
    conn = connection.create_connection(
           ^^^^^^^^^^^^^^^^^^^^^^^^^^^^^
  File "/home/airflow/.local/lib/python3.12/site-packages/snowflake/connector/vendored/urllib3/util/connection.py", line 79, in create_connection
    for res in socket.getaddrinfo(host, port, family, socket.SOCK_STREAM):
               ^^^^^^^^^^^^^^^^^^^^^^^^^^^^^^^^^^^^^^^^^^^^^^^^^^^^^^^^^^
  File "/usr/local/lib/python3.12/socket.py", line 978, in getaddrinfo
    for res in _socket.getaddrinfo(host, port, family, type, proto, flags):
               ^^^^^^^^^^^^^^^^^^^^^^^^^^^^^^^^^^^^^^^^^^^^^^^^^^^^^^^^^^^
socket.gaierror: [Errno -2] Name or service not known

During handling of the above exception, another exception occurred:

Traceback (most recent call last):
  File "/home/airflow/.local/lib/python3.12/site-packages/snowflake/connector/vendored/urllib3/connectionpool.py", line 715, in urlopen
    httplib_response = self._make_request(
                       ^^^^^^^^^^^^^^^^^^^
  File "/home/airflow/.local/lib/python3.12/site-packages/snowflake/connector/vendored/urllib3/connectionpool.py", line 404, in _make_request
    self._validate_conn(conn)
  File "/home/airflow/.local/lib/python3.12/site-packages/snowflake/connector/vendored/urllib3/connectionpool.py", line 1058, in _validate_conn
    conn.connect()
  File "/home/airflow/.local/lib/python3.12/site-packages/snowflake/connector/vendored/urllib3/connection.py", line 363, in connect
    self.sock = conn = self._new_conn()
                       ^^^^^^^^^^^^^^^^
  File "/home/airflow/.local/lib/python3.12/site-packages/snowflake/connector/vendored/urllib3/connection.py", line 186, in _new_conn
    raise NewConnectionError(
snowflake.connector.vendored.urllib3.exceptions.NewConnectionError: <snowflake.connector.vendored.urllib3.connection.HTTPSConnection object at 0x7fdf44dd8b60>: Failed to establish a new connection: [Errno -2] Name or service not known

During handling of the above exception, another exception occurred:

Traceback (most recent call last):
  File "/home/airflow/.local/lib/python3.12/site-packages/snowflake/connector/vendored/requests/adapters.py", line 486, in send
    resp = conn.urlopen(
           ^^^^^^^^^^^^^
  File "/home/airflow/.local/lib/python3.12/site-packages/snowflake/connector/vendored/urllib3/connectionpool.py", line 827, in urlopen
    return self.urlopen(
           ^^^^^^^^^^^^^
  File "/home/airflow/.local/lib/python3.12/site-packages/snowflake/connector/vendored/urllib3/connectionpool.py", line 799, in urlopen
    retries = retries.increment(
              ^^^^^^^^^^^^^^^^^^
  File "/home/airflow/.local/lib/python3.12/site-packages/snowflake/connector/vendored/urllib3/util/retry.py", line 592, in increment
    raise MaxRetryError(_pool, url, error or ResponseError(cause))
snowflake.connector.vendored.urllib3.exceptions.MaxRetryError: HTTPSConnectionPool(host='sfedu02-pdb57018.us%20west%20(oregon).snowflakecomputing.com', port=443): Max retries exceeded with url: /session/v1/login-request?request_id=7814ed98-ec9c-4a97-9fcd-b03e5e5f60c0&databaseName=dbt_db&schemaName=dbt_schema&warehouse=dbt_wh&roleName=dbt_role&request_guid=238da89b-9952-4013-a89f-2685c7e015ed (Caused by NewConnectionError('<snowflake.connector.vendored.urllib3.connection.HTTPSConnection object at 0x7fdf44dd8b60>: Failed to establish a new connection: [Errno -2] Name or service not known'))

During handling of the above exception, another exception occurred:

Traceback (most recent call last):
  File "/home/airflow/.local/lib/python3.12/site-packages/snowflake/connector/network.py", line 1081, in _request_exec
    raw_ret = session.request(
              ^^^^^^^^^^^^^^^^
  File "/home/airflow/.local/lib/python3.12/site-packages/snowflake/connector/vendored/requests/sessions.py", line 589, in request
    resp = self.send(prep, **send_kwargs)
           ^^^^^^^^^^^^^^^^^^^^^^^^^^^^^^
  File "/home/airflow/.local/lib/python3.12/site-packages/snowflake/connector/vendored/requests/sessions.py", line 703, in send
    r = adapter.send(request, **kwargs)
        ^^^^^^^^^^^^^^^^^^^^^^^^^^^^^^^
  File "/home/airflow/.local/lib/python3.12/site-packages/snowflake/connector/vendored/requests/adapters.py", line 519, in send
    raise ConnectionError(e, request=request)
snowflake.connector.vendored.requests.exceptions.ConnectionError: HTTPSConnectionPool(host='sfedu02-pdb57018.us%20west%20(oregon).snowflakecomputing.com', port=443): Max retries exceeded with url: /session/v1/login-request?request_id=7814ed98-ec9c-4a97-9fcd-b03e5e5f60c0&databaseName=dbt_db&schemaName=dbt_schema&warehouse=dbt_wh&roleName=dbt_role&request_guid=238da89b-9952-4013-a89f-2685c7e015ed (Caused by NewConnectionError('<snowflake.connector.vendored.urllib3.connection.HTTPSConnection object at 0x7fdf44dd8b60>: Failed to establish a new connection: [Errno -2] Name or service not known'))

During handling of the above exception, another exception occurred:

Traceback (most recent call last):
  File "/home/airflow/.local/lib/python3.12/site-packages/snowflake/connector/connection.py", line 1432, in _authenticate
    auth.authenticate(
  File "/home/airflow/.local/lib/python3.12/site-packages/snowflake/connector/auth/_auth.py", line 265, in authenticate
    ret = self._rest._post_request(
          ^^^^^^^^^^^^^^^^^^^^^^^^^
  File "/home/airflow/.local/lib/python3.12/site-packages/snowflake/connector/network.py", line 749, in _post_request
    ret = self.fetch(
          ^^^^^^^^^^^
  File "/home/airflow/.local/lib/python3.12/site-packages/snowflake/connector/network.py", line 864, in fetch
    ret = self._request_exec_wrapper(
          ^^^^^^^^^^^^^^^^^^^^^^^^^^^
  File "/home/airflow/.local/lib/python3.12/site-packages/snowflake/connector/network.py", line 992, in _request_exec_wrapper
    raise e
  File "/home/airflow/.local/lib/python3.12/site-packages/snowflake/connector/network.py", line 914, in _request_exec_wrapper
    return_object = self._request_exec(
                    ^^^^^^^^^^^^^^^^^^^
  File "/home/airflow/.local/lib/python3.12/site-packages/snowflake/connector/network.py", line 1179, in _request_exec
    raise OperationalError(
snowflake.connector.errors.OperationalError: 251011: 251011: ConnectionTimeout occurred during login. Will be handled by authenticator

The above exception was the direct cause of the following exception:

Traceback (most recent call last):
  File "/home/airflow/.local/lib/python3.12/site-packages/airflow/models/taskinstance.py", line 768, in _execute_task
    result = _execute_callable(context=context, **execute_callable_kwargs)
             ^^^^^^^^^^^^^^^^^^^^^^^^^^^^^^^^^^^^^^^^^^^^^^^^^^^^^^^^^^^^^
  File "/home/airflow/.local/lib/python3.12/site-packages/airflow/models/taskinstance.py", line 734, in _execute_callable
    return ExecutionCallableRunner(
           ^^^^^^^^^^^^^^^^^^^^^^^^
  File "/home/airflow/.local/lib/python3.12/site-packages/airflow/utils/operator_helpers.py", line 252, in run
    return self.func(*args, **kwargs)
           ^^^^^^^^^^^^^^^^^^^^^^^^^^
  File "/home/airflow/.local/lib/python3.12/site-packages/airflow/models/baseoperator.py", line 424, in wrapper
    return func(self, *args, **kwargs)
           ^^^^^^^^^^^^^^^^^^^^^^^^^^^
  File "/home/airflow/.local/lib/python3.12/site-packages/airflow/providers/common/sql/operators/sql.py", line 301, in execute
    output = hook.run(
             ^^^^^^^^^
  File "/home/airflow/.local/lib/python3.12/site-packages/airflow/providers/snowflake/hooks/snowflake.py", line 391, in run
    with closing(self.get_conn()) as conn:
                 ^^^^^^^^^^^^^^^
  File "/home/airflow/.local/lib/python3.12/site-packages/airflow/providers/snowflake/hooks/snowflake.py", line 289, in get_conn
    conn = connector.connect(**conn_config)
           ^^^^^^^^^^^^^^^^^^^^^^^^^^^^^^^^
  File "/home/airflow/.local/lib/python3.12/site-packages/snowflake/connector/__init__.py", line 55, in Connect
    return SnowflakeConnection(**kwargs)
           ^^^^^^^^^^^^^^^^^^^^^^^^^^^^^
  File "/home/airflow/.local/lib/python3.12/site-packages/snowflake/connector/connection.py", line 467, in __init__
    self.connect(**kwargs)
  File "/home/airflow/.local/lib/python3.12/site-packages/snowflake/connector/connection.py", line 786, in connect
    self.__open_connection()
  File "/home/airflow/.local/lib/python3.12/site-packages/snowflake/connector/connection.py", line 1116, in __open_connection
    self.authenticate_with_retry(self.auth_class)
  File "/home/airflow/.local/lib/python3.12/site-packages/snowflake/connector/connection.py", line 1404, in authenticate_with_retry
    self._authenticate(auth_instance)
  File "/home/airflow/.local/lib/python3.12/site-packages/snowflake/connector/connection.py", line 1478, in _authenticate
    raise auth_op from e
  File "/home/airflow/.local/lib/python3.12/site-packages/snowflake/connector/connection.py", line 1453, in _authenticate
    auth_instance.handle_timeout(
  File "/home/airflow/.local/lib/python3.12/site-packages/snowflake/connector/auth/by_plugin.py", line 213, in handle_timeout
    raise error
snowflake.connector.errors.OperationalError: 250001: 250001: Could not connect to Snowflake backend after 2 attempt(s).Aborting
[2025-02-14T10:04:28.215+0000] {taskinstance.py:1226} INFO - Marking task as FAILED. dag_id=check_all_snowflake_tables, task_id=check_tables_existence, run_id=manual__2025-02-14T10:04:19.180713+00:00, execution_date=20250214T100419, start_date=20250214T100426, end_date=20250214T100428
[2025-02-14T10:04:28.412+0000] {taskinstance.py:341} INFO - ::group::Post task execution logs
[2025-02-14T10:04:28.415+0000] {standard_task_runner.py:124} ERROR - Failed to execute job 67 for task check_tables_existence (250001: 250001: Could not connect to Snowflake backend after 2 attempt(s).Aborting; 59)
Traceback (most recent call last):
  File "/home/airflow/.local/lib/python3.12/site-packages/snowflake/connector/vendored/urllib3/connection.py", line 174, in _new_conn
    conn = connection.create_connection(
           ^^^^^^^^^^^^^^^^^^^^^^^^^^^^^
  File "/home/airflow/.local/lib/python3.12/site-packages/snowflake/connector/vendored/urllib3/util/connection.py", line 79, in create_connection
    for res in socket.getaddrinfo(host, port, family, socket.SOCK_STREAM):
               ^^^^^^^^^^^^^^^^^^^^^^^^^^^^^^^^^^^^^^^^^^^^^^^^^^^^^^^^^^
  File "/usr/local/lib/python3.12/socket.py", line 978, in getaddrinfo
    for res in _socket.getaddrinfo(host, port, family, type, proto, flags):
               ^^^^^^^^^^^^^^^^^^^^^^^^^^^^^^^^^^^^^^^^^^^^^^^^^^^^^^^^^^^
socket.gaierror: [Errno -2] Name or service not known

During handling of the above exception, another exception occurred:

Traceback (most recent call last):
  File "/home/airflow/.local/lib/python3.12/site-packages/snowflake/connector/vendored/urllib3/connectionpool.py", line 715, in urlopen
    httplib_response = self._make_request(
                       ^^^^^^^^^^^^^^^^^^^
  File "/home/airflow/.local/lib/python3.12/site-packages/snowflake/connector/vendored/urllib3/connectionpool.py", line 404, in _make_request
    self._validate_conn(conn)
  File "/home/airflow/.local/lib/python3.12/site-packages/snowflake/connector/vendored/urllib3/connectionpool.py", line 1058, in _validate_conn
    conn.connect()
  File "/home/airflow/.local/lib/python3.12/site-packages/snowflake/connector/vendored/urllib3/connection.py", line 363, in connect
    self.sock = conn = self._new_conn()
                       ^^^^^^^^^^^^^^^^
  File "/home/airflow/.local/lib/python3.12/site-packages/snowflake/connector/vendored/urllib3/connection.py", line 186, in _new_conn
    raise NewConnectionError(
snowflake.connector.vendored.urllib3.exceptions.NewConnectionError: <snowflake.connector.vendored.urllib3.connection.HTTPSConnection object at 0x7fdf44dd8b60>: Failed to establish a new connection: [Errno -2] Name or service not known

During handling of the above exception, another exception occurred:

Traceback (most recent call last):
  File "/home/airflow/.local/lib/python3.12/site-packages/snowflake/connector/vendored/requests/adapters.py", line 486, in send
    resp = conn.urlopen(
           ^^^^^^^^^^^^^
  File "/home/airflow/.local/lib/python3.12/site-packages/snowflake/connector/vendored/urllib3/connectionpool.py", line 827, in urlopen
    return self.urlopen(
           ^^^^^^^^^^^^^
  File "/home/airflow/.local/lib/python3.12/site-packages/snowflake/connector/vendored/urllib3/connectionpool.py", line 799, in urlopen
    retries = retries.increment(
              ^^^^^^^^^^^^^^^^^^
  File "/home/airflow/.local/lib/python3.12/site-packages/snowflake/connector/vendored/urllib3/util/retry.py", line 592, in increment
    raise MaxRetryError(_pool, url, error or ResponseError(cause))
snowflake.connector.vendored.urllib3.exceptions.MaxRetryError: HTTPSConnectionPool(host='sfedu02-pdb57018.us%20west%20(oregon).snowflakecomputing.com', port=443): Max retries exceeded with url: /session/v1/login-request?request_id=7814ed98-ec9c-4a97-9fcd-b03e5e5f60c0&databaseName=dbt_db&schemaName=dbt_schema&warehouse=dbt_wh&roleName=dbt_role&request_guid=238da89b-9952-4013-a89f-2685c7e015ed (Caused by NewConnectionError('<snowflake.connector.vendored.urllib3.connection.HTTPSConnection object at 0x7fdf44dd8b60>: Failed to establish a new connection: [Errno -2] Name or service not known'))

During handling of the above exception, another exception occurred:

Traceback (most recent call last):
  File "/home/airflow/.local/lib/python3.12/site-packages/snowflake/connector/network.py", line 1081, in _request_exec
    raw_ret = session.request(
              ^^^^^^^^^^^^^^^^
  File "/home/airflow/.local/lib/python3.12/site-packages/snowflake/connector/vendored/requests/sessions.py", line 589, in request
    resp = self.send(prep, **send_kwargs)
           ^^^^^^^^^^^^^^^^^^^^^^^^^^^^^^
  File "/home/airflow/.local/lib/python3.12/site-packages/snowflake/connector/vendored/requests/sessions.py", line 703, in send
    r = adapter.send(request, **kwargs)
        ^^^^^^^^^^^^^^^^^^^^^^^^^^^^^^^
  File "/home/airflow/.local/lib/python3.12/site-packages/snowflake/connector/vendored/requests/adapters.py", line 519, in send
    raise ConnectionError(e, request=request)
snowflake.connector.vendored.requests.exceptions.ConnectionError: HTTPSConnectionPool(host='sfedu02-pdb57018.us%20west%20(oregon).snowflakecomputing.com', port=443): Max retries exceeded with url: /session/v1/login-request?request_id=7814ed98-ec9c-4a97-9fcd-b03e5e5f60c0&databaseName=dbt_db&schemaName=dbt_schema&warehouse=dbt_wh&roleName=dbt_role&request_guid=238da89b-9952-4013-a89f-2685c7e015ed (Caused by NewConnectionError('<snowflake.connector.vendored.urllib3.connection.HTTPSConnection object at 0x7fdf44dd8b60>: Failed to establish a new connection: [Errno -2] Name or service not known'))

During handling of the above exception, another exception occurred:

Traceback (most recent call last):
  File "/home/airflow/.local/lib/python3.12/site-packages/snowflake/connector/connection.py", line 1432, in _authenticate
    auth.authenticate(
  File "/home/airflow/.local/lib/python3.12/site-packages/snowflake/connector/auth/_auth.py", line 265, in authenticate
    ret = self._rest._post_request(
          ^^^^^^^^^^^^^^^^^^^^^^^^^
  File "/home/airflow/.local/lib/python3.12/site-packages/snowflake/connector/network.py", line 749, in _post_request
    ret = self.fetch(
          ^^^^^^^^^^^
  File "/home/airflow/.local/lib/python3.12/site-packages/snowflake/connector/network.py", line 864, in fetch
    ret = self._request_exec_wrapper(
          ^^^^^^^^^^^^^^^^^^^^^^^^^^^
  File "/home/airflow/.local/lib/python3.12/site-packages/snowflake/connector/network.py", line 992, in _request_exec_wrapper
    raise e
  File "/home/airflow/.local/lib/python3.12/site-packages/snowflake/connector/network.py", line 914, in _request_exec_wrapper
    return_object = self._request_exec(
                    ^^^^^^^^^^^^^^^^^^^
  File "/home/airflow/.local/lib/python3.12/site-packages/snowflake/connector/network.py", line 1179, in _request_exec
    raise OperationalError(
snowflake.connector.errors.OperationalError: 251011: 251011: ConnectionTimeout occurred during login. Will be handled by authenticator

The above exception was the direct cause of the following exception:

Traceback (most recent call last):
  File "/home/airflow/.local/lib/python3.12/site-packages/airflow/task/task_runner/standard_task_runner.py", line 117, in _start_by_fork
    ret = args.func(args, dag=self.dag)
          ^^^^^^^^^^^^^^^^^^^^^^^^^^^^^
  File "/home/airflow/.local/lib/python3.12/site-packages/airflow/cli/cli_config.py", line 49, in command
    return func(*args, **kwargs)
           ^^^^^^^^^^^^^^^^^^^^^
  File "/home/airflow/.local/lib/python3.12/site-packages/airflow/utils/cli.py", line 116, in wrapper
    return f(*args, **kwargs)
           ^^^^^^^^^^^^^^^^^^
  File "/home/airflow/.local/lib/python3.12/site-packages/airflow/cli/commands/task_command.py", line 483, in task_run
    task_return_code = _run_task_by_selected_method(args, _dag, ti)
                       ^^^^^^^^^^^^^^^^^^^^^^^^^^^^^^^^^^^^^^^^^^^^
  File "/home/airflow/.local/lib/python3.12/site-packages/airflow/cli/commands/task_command.py", line 256, in _run_task_by_selected_method
    return _run_raw_task(args, ti)
           ^^^^^^^^^^^^^^^^^^^^^^^
  File "/home/airflow/.local/lib/python3.12/site-packages/airflow/cli/commands/task_command.py", line 341, in _run_raw_task
    return ti._run_raw_task(
           ^^^^^^^^^^^^^^^^^
  File "/home/airflow/.local/lib/python3.12/site-packages/airflow/utils/session.py", line 97, in wrapper
    return func(*args, session=session, **kwargs)
           ^^^^^^^^^^^^^^^^^^^^^^^^^^^^^^^^^^^^^^
  File "/home/airflow/.local/lib/python3.12/site-packages/airflow/models/taskinstance.py", line 3006, in _run_raw_task
    return _run_raw_task(
           ^^^^^^^^^^^^^^
  File "/home/airflow/.local/lib/python3.12/site-packages/airflow/models/taskinstance.py", line 274, in _run_raw_task
    TaskInstance._execute_task_with_callbacks(
  File "/home/airflow/.local/lib/python3.12/site-packages/airflow/models/taskinstance.py", line 3161, in _execute_task_with_callbacks
    result = self._execute_task(context, task_orig)
             ^^^^^^^^^^^^^^^^^^^^^^^^^^^^^^^^^^^^^^
  File "/home/airflow/.local/lib/python3.12/site-packages/airflow/models/taskinstance.py", line 3185, in _execute_task
    return _execute_task(self, context, task_orig)
           ^^^^^^^^^^^^^^^^^^^^^^^^^^^^^^^^^^^^^^^
  File "/home/airflow/.local/lib/python3.12/site-packages/airflow/models/taskinstance.py", line 768, in _execute_task
    result = _execute_callable(context=context, **execute_callable_kwargs)
             ^^^^^^^^^^^^^^^^^^^^^^^^^^^^^^^^^^^^^^^^^^^^^^^^^^^^^^^^^^^^^
  File "/home/airflow/.local/lib/python3.12/site-packages/airflow/models/taskinstance.py", line 734, in _execute_callable
    return ExecutionCallableRunner(
           ^^^^^^^^^^^^^^^^^^^^^^^^
  File "/home/airflow/.local/lib/python3.12/site-packages/airflow/utils/operator_helpers.py", line 252, in run
    return self.func(*args, **kwargs)
           ^^^^^^^^^^^^^^^^^^^^^^^^^^
  File "/home/airflow/.local/lib/python3.12/site-packages/airflow/models/baseoperator.py", line 424, in wrapper
    return func(self, *args, **kwargs)
           ^^^^^^^^^^^^^^^^^^^^^^^^^^^
  File "/home/airflow/.local/lib/python3.12/site-packages/airflow/providers/common/sql/operators/sql.py", line 301, in execute
    output = hook.run(
             ^^^^^^^^^
  File "/home/airflow/.local/lib/python3.12/site-packages/airflow/providers/snowflake/hooks/snowflake.py", line 391, in run
    with closing(self.get_conn()) as conn:
                 ^^^^^^^^^^^^^^^
  File "/home/airflow/.local/lib/python3.12/site-packages/airflow/providers/snowflake/hooks/snowflake.py", line 289, in get_conn
    conn = connector.connect(**conn_config)
           ^^^^^^^^^^^^^^^^^^^^^^^^^^^^^^^^
  File "/home/airflow/.local/lib/python3.12/site-packages/snowflake/connector/__init__.py", line 55, in Connect
    return SnowflakeConnection(**kwargs)
           ^^^^^^^^^^^^^^^^^^^^^^^^^^^^^
  File "/home/airflow/.local/lib/python3.12/site-packages/snowflake/connector/connection.py", line 467, in __init__
    self.connect(**kwargs)
  File "/home/airflow/.local/lib/python3.12/site-packages/snowflake/connector/connection.py", line 786, in connect
    self.__open_connection()
  File "/home/airflow/.local/lib/python3.12/site-packages/snowflake/connector/connection.py", line 1116, in __open_connection
    self.authenticate_with_retry(self.auth_class)
  File "/home/airflow/.local/lib/python3.12/site-packages/snowflake/connector/connection.py", line 1404, in authenticate_with_retry
    self._authenticate(auth_instance)
  File "/home/airflow/.local/lib/python3.12/site-packages/snowflake/connector/connection.py", line 1478, in _authenticate
    raise auth_op from e
  File "/home/airflow/.local/lib/python3.12/site-packages/snowflake/connector/connection.py", line 1453, in _authenticate
    auth_instance.handle_timeout(
  File "/home/airflow/.local/lib/python3.12/site-packages/snowflake/connector/auth/by_plugin.py", line 213, in handle_timeout
    raise error
snowflake.connector.errors.OperationalError: 250001: 250001: Could not connect to Snowflake backend after 2 attempt(s).Aborting
[2025-02-14T10:04:28.475+0000] {local_task_job_runner.py:266} INFO - Task exited with return code 1
[2025-02-14T10:04:28.548+0000] {taskinstance.py:3901} INFO - 0 downstream tasks scheduled from follow-on schedule check
[2025-02-14T10:04:28.591+0000] {local_task_job_runner.py:245} INFO - ::endgroup::
