[2025-02-14T19:21:16.169+0000] {local_task_job_runner.py:123} INFO - ::group::Pre task execution logs
[2025-02-14T19:21:16.191+0000] {taskinstance.py:2614} INFO - Dependencies all met for dep_context=non-requeueable deps ti=<TaskInstance: dbt_data_pipeline.run_dbt_models manual__2025-02-14T19:10:46.600231+00:00 [queued]>
[2025-02-14T19:21:16.200+0000] {taskinstance.py:2614} INFO - Dependencies all met for dep_context=requeueable deps ti=<TaskInstance: dbt_data_pipeline.run_dbt_models manual__2025-02-14T19:10:46.600231+00:00 [queued]>
[2025-02-14T19:21:16.201+0000] {taskinstance.py:2867} INFO - Starting attempt 2 of 2
[2025-02-14T19:21:16.215+0000] {taskinstance.py:2890} INFO - Executing <Task(BashOperator): run_dbt_models> on 2025-02-14 19:10:46.600231+00:00
[2025-02-14T19:21:16.220+0000] {warnings.py:112} WARNING - /home/***/.local/lib/python3.12/site-packages/***/task/task_runner/standard_task_runner.py:70: DeprecationWarning: This process (pid=159) is multi-threaded, use of fork() may lead to deadlocks in the child.
  pid = os.fork()

[2025-02-14T19:21:16.222+0000] {standard_task_runner.py:72} INFO - Started process 160 to run task
[2025-02-14T19:21:16.222+0000] {standard_task_runner.py:104} INFO - Running: ['***', 'tasks', 'run', 'dbt_data_pipeline', 'run_dbt_models', 'manual__2025-02-14T19:10:46.600231+00:00', '--job-id', '162', '--raw', '--subdir', 'DAGS_FOLDER/dbt-chck.py', '--cfg-path', '/tmp/tmpnjihp1p8']
[2025-02-14T19:21:16.224+0000] {standard_task_runner.py:105} INFO - Job 162: Subtask run_dbt_models
[2025-02-14T19:21:16.266+0000] {task_command.py:467} INFO - Running <TaskInstance: dbt_data_pipeline.run_dbt_models manual__2025-02-14T19:10:46.600231+00:00 [running]> on host e9f6bf018f11
[2025-02-14T19:21:16.332+0000] {taskinstance.py:3134} INFO - Exporting env vars: AIRFLOW_CTX_DAG_OWNER='***' AIRFLOW_CTX_DAG_ID='dbt_data_pipeline' AIRFLOW_CTX_TASK_ID='run_dbt_models' AIRFLOW_CTX_EXECUTION_DATE='2025-02-14T19:10:46.600231+00:00' AIRFLOW_CTX_TRY_NUMBER='2' AIRFLOW_CTX_DAG_RUN_ID='manual__2025-02-14T19:10:46.600231+00:00'
[2025-02-14T19:21:16.334+0000] {taskinstance.py:732} INFO - ::endgroup::
[2025-02-14T19:21:16.347+0000] {subprocess.py:78} INFO - Tmp dir root location: /tmp
[2025-02-14T19:21:16.349+0000] {subprocess.py:88} INFO - Running command: ['/usr/bin/bash', '-c', 'cd /opt/***/dbt/data_pipeline && dbt run']
[2025-02-14T19:21:16.359+0000] {subprocess.py:99} INFO - Output:
[2025-02-14T19:21:18.292+0000] {subprocess.py:106} INFO - Usage: dbt run [OPTIONS]
[2025-02-14T19:21:18.292+0000] {subprocess.py:106} INFO - Try 'dbt run -h' for help.
[2025-02-14T19:21:18.293+0000] {subprocess.py:106} INFO - 
[2025-02-14T19:21:18.294+0000] {subprocess.py:106} INFO - Error: Invalid value for '--profiles-dir': Path '/home/***/.dbt' does not exist.
[2025-02-14T19:21:18.477+0000] {subprocess.py:110} INFO - Command exited with return code 2
[2025-02-14T19:21:18.487+0000] {taskinstance.py:3313} ERROR - Task failed with exception
Traceback (most recent call last):
  File "/home/airflow/.local/lib/python3.12/site-packages/airflow/models/taskinstance.py", line 768, in _execute_task
    result = _execute_callable(context=context, **execute_callable_kwargs)
             ^^^^^^^^^^^^^^^^^^^^^^^^^^^^^^^^^^^^^^^^^^^^^^^^^^^^^^^^^^^^^
  File "/home/airflow/.local/lib/python3.12/site-packages/airflow/models/taskinstance.py", line 734, in _execute_callable
    return ExecutionCallableRunner(
           ^^^^^^^^^^^^^^^^^^^^^^^^
  File "/home/airflow/.local/lib/python3.12/site-packages/airflow/utils/operator_helpers.py", line 252, in run
    return self.func(*args, **kwargs)
           ^^^^^^^^^^^^^^^^^^^^^^^^^^
  File "/home/airflow/.local/lib/python3.12/site-packages/airflow/models/baseoperator.py", line 424, in wrapper
    return func(self, *args, **kwargs)
           ^^^^^^^^^^^^^^^^^^^^^^^^^^^
  File "/home/airflow/.local/lib/python3.12/site-packages/airflow/operators/bash.py", line 276, in execute
    raise AirflowException(
airflow.exceptions.AirflowException: Bash command failed. The command returned a non-zero exit code 2.
[2025-02-14T19:21:18.491+0000] {taskinstance.py:1226} INFO - Marking task as FAILED. dag_id=dbt_data_pipeline, task_id=run_dbt_models, run_id=manual__2025-02-14T19:10:46.600231+00:00, execution_date=20250214T191046, start_date=20250214T192116, end_date=20250214T192118
[2025-02-14T19:21:18.522+0000] {taskinstance.py:341} INFO - ::group::Post task execution logs
[2025-02-14T19:21:18.522+0000] {standard_task_runner.py:124} ERROR - Failed to execute job 162 for task run_dbt_models (Bash command failed. The command returned a non-zero exit code 2.; 160)
Traceback (most recent call last):
  File "/home/airflow/.local/lib/python3.12/site-packages/airflow/task/task_runner/standard_task_runner.py", line 117, in _start_by_fork
    ret = args.func(args, dag=self.dag)
          ^^^^^^^^^^^^^^^^^^^^^^^^^^^^^
  File "/home/airflow/.local/lib/python3.12/site-packages/airflow/cli/cli_config.py", line 49, in command
    return func(*args, **kwargs)
           ^^^^^^^^^^^^^^^^^^^^^
  File "/home/airflow/.local/lib/python3.12/site-packages/airflow/utils/cli.py", line 116, in wrapper
    return f(*args, **kwargs)
           ^^^^^^^^^^^^^^^^^^
  File "/home/airflow/.local/lib/python3.12/site-packages/airflow/cli/commands/task_command.py", line 483, in task_run
    task_return_code = _run_task_by_selected_method(args, _dag, ti)
                       ^^^^^^^^^^^^^^^^^^^^^^^^^^^^^^^^^^^^^^^^^^^^
  File "/home/airflow/.local/lib/python3.12/site-packages/airflow/cli/commands/task_command.py", line 256, in _run_task_by_selected_method
    return _run_raw_task(args, ti)
           ^^^^^^^^^^^^^^^^^^^^^^^
  File "/home/airflow/.local/lib/python3.12/site-packages/airflow/cli/commands/task_command.py", line 341, in _run_raw_task
    return ti._run_raw_task(
           ^^^^^^^^^^^^^^^^^
  File "/home/airflow/.local/lib/python3.12/site-packages/airflow/utils/session.py", line 97, in wrapper
    return func(*args, session=session, **kwargs)
           ^^^^^^^^^^^^^^^^^^^^^^^^^^^^^^^^^^^^^^
  File "/home/airflow/.local/lib/python3.12/site-packages/airflow/models/taskinstance.py", line 3006, in _run_raw_task
    return _run_raw_task(
           ^^^^^^^^^^^^^^
  File "/home/airflow/.local/lib/python3.12/site-packages/airflow/models/taskinstance.py", line 274, in _run_raw_task
    TaskInstance._execute_task_with_callbacks(
  File "/home/airflow/.local/lib/python3.12/site-packages/airflow/models/taskinstance.py", line 3161, in _execute_task_with_callbacks
    result = self._execute_task(context, task_orig)
             ^^^^^^^^^^^^^^^^^^^^^^^^^^^^^^^^^^^^^^
  File "/home/airflow/.local/lib/python3.12/site-packages/airflow/models/taskinstance.py", line 3185, in _execute_task
    return _execute_task(self, context, task_orig)
           ^^^^^^^^^^^^^^^^^^^^^^^^^^^^^^^^^^^^^^^
  File "/home/airflow/.local/lib/python3.12/site-packages/airflow/models/taskinstance.py", line 768, in _execute_task
    result = _execute_callable(context=context, **execute_callable_kwargs)
             ^^^^^^^^^^^^^^^^^^^^^^^^^^^^^^^^^^^^^^^^^^^^^^^^^^^^^^^^^^^^^
  File "/home/airflow/.local/lib/python3.12/site-packages/airflow/models/taskinstance.py", line 734, in _execute_callable
    return ExecutionCallableRunner(
           ^^^^^^^^^^^^^^^^^^^^^^^^
  File "/home/airflow/.local/lib/python3.12/site-packages/airflow/utils/operator_helpers.py", line 252, in run
    return self.func(*args, **kwargs)
           ^^^^^^^^^^^^^^^^^^^^^^^^^^
  File "/home/airflow/.local/lib/python3.12/site-packages/airflow/models/baseoperator.py", line 424, in wrapper
    return func(self, *args, **kwargs)
           ^^^^^^^^^^^^^^^^^^^^^^^^^^^
  File "/home/airflow/.local/lib/python3.12/site-packages/airflow/operators/bash.py", line 276, in execute
    raise AirflowException(
airflow.exceptions.AirflowException: Bash command failed. The command returned a non-zero exit code 2.
[2025-02-14T19:21:18.568+0000] {local_task_job_runner.py:266} INFO - Task exited with return code 1
[2025-02-14T19:21:18.578+0000] {local_task_job_runner.py:245} INFO - ::endgroup::
