[2025-02-14T19:12:13.852+0000] {local_task_job_runner.py:123} INFO - ::group::Pre task execution logs
[2025-02-14T19:12:13.928+0000] {taskinstance.py:2614} INFO - Dependencies all met for dep_context=non-requeueable deps ti=<TaskInstance: dbt_snowflake_dag.dbt_debug scheduled__2025-02-13T00:00:00+00:00 [queued]>
[2025-02-14T19:12:13.954+0000] {taskinstance.py:2614} INFO - Dependencies all met for dep_context=requeueable deps ti=<TaskInstance: dbt_snowflake_dag.dbt_debug scheduled__2025-02-13T00:00:00+00:00 [queued]>
[2025-02-14T19:12:13.956+0000] {taskinstance.py:2867} INFO - Starting attempt 1 of 2
[2025-02-14T19:12:14.014+0000] {taskinstance.py:2890} INFO - Executing <Task(BashOperator): dbt_debug> on 2025-02-13 00:00:00+00:00
[2025-02-14T19:12:14.038+0000] {warnings.py:112} WARNING - /home/***/.local/lib/python3.12/site-packages/***/task/task_runner/standard_task_runner.py:70: DeprecationWarning: This process (pid=80) is multi-threaded, use of fork() may lead to deadlocks in the child.
  pid = os.fork()

[2025-02-14T19:12:14.054+0000] {standard_task_runner.py:72} INFO - Started process 82 to run task
[2025-02-14T19:12:14.059+0000] {standard_task_runner.py:104} INFO - Running: ['***', 'tasks', 'run', 'dbt_snowflake_dag', 'dbt_debug', 'scheduled__2025-02-13T00:00:00+00:00', '--job-id', '146', '--raw', '--subdir', 'DAGS_FOLDER/dbt-chck.py', '--cfg-path', '/tmp/tmpmqqd1ihr']
[2025-02-14T19:12:14.082+0000] {standard_task_runner.py:105} INFO - Job 146: Subtask dbt_debug
[2025-02-14T19:12:14.363+0000] {task_command.py:467} INFO - Running <TaskInstance: dbt_snowflake_dag.dbt_debug scheduled__2025-02-13T00:00:00+00:00 [running]> on host e9f6bf018f11
[2025-02-14T19:12:14.742+0000] {taskinstance.py:3134} INFO - Exporting env vars: AIRFLOW_CTX_DAG_OWNER='***' AIRFLOW_CTX_DAG_ID='dbt_snowflake_dag' AIRFLOW_CTX_TASK_ID='dbt_debug' AIRFLOW_CTX_EXECUTION_DATE='2025-02-13T00:00:00+00:00' AIRFLOW_CTX_TRY_NUMBER='1' AIRFLOW_CTX_DAG_RUN_ID='scheduled__2025-02-13T00:00:00+00:00'
[2025-02-14T19:12:14.751+0000] {taskinstance.py:732} INFO - ::endgroup::
[2025-02-14T19:12:14.810+0000] {subprocess.py:78} INFO - Tmp dir root location: /tmp
[2025-02-14T19:12:14.814+0000] {subprocess.py:88} INFO - Running command: ['/usr/bin/bash', '-c', 'dbt debug --profiles-dir /opt/***/dbt']
[2025-02-14T19:12:14.854+0000] {subprocess.py:99} INFO - Output:
[2025-02-14T19:12:25.598+0000] {subprocess.py:106} INFO - [0m19:12:25  Running with dbt=1.9.2
[2025-02-14T19:12:25.641+0000] {subprocess.py:106} INFO - [0m19:12:25  dbt version: 1.9.2
[2025-02-14T19:12:25.644+0000] {subprocess.py:106} INFO - [0m19:12:25  python version: 3.12.9
[2025-02-14T19:12:25.648+0000] {subprocess.py:106} INFO - [0m19:12:25  python path: /home/***/.local/bin/python
[2025-02-14T19:12:25.663+0000] {subprocess.py:106} INFO - [0m19:12:25  os info: Linux-5.15.133.1-microsoft-standard-WSL2-x86_64-with-glibc2.36
[2025-02-14T19:12:25.664+0000] {subprocess.py:106} INFO - [0m19:12:25  Using profiles dir at /opt/***/dbt
[2025-02-14T19:12:25.668+0000] {subprocess.py:106} INFO - [0m19:12:25  Using profiles.yml file at /opt/***/dbt/profiles.yml
[2025-02-14T19:12:25.670+0000] {subprocess.py:106} INFO - [0m19:12:25  Using dbt_project.yml file at /tmp/***tmpjtdxmxq1/dbt_project.yml
[2025-02-14T19:12:25.673+0000] {subprocess.py:106} INFO - [0m19:12:25  Configuration:
[2025-02-14T19:12:25.674+0000] {subprocess.py:106} INFO - [0m19:12:25    profiles.yml file [[31mERROR not found[0m]
[2025-02-14T19:12:25.675+0000] {subprocess.py:106} INFO - [0m19:12:25    dbt_project.yml file [[31mERROR not found[0m]
[2025-02-14T19:12:25.677+0000] {subprocess.py:106} INFO - [0m19:12:25  Required dependencies:
[2025-02-14T19:12:25.694+0000] {subprocess.py:106} INFO - [0m19:12:25   - git [[31mERROR[0m]
[2025-02-14T19:12:25.695+0000] {subprocess.py:106} INFO - 
[2025-02-14T19:12:25.697+0000] {subprocess.py:106} INFO - [0m19:12:25  Connection test skipped since no profile was found
[2025-02-14T19:12:25.700+0000] {subprocess.py:106} INFO - [0m19:12:25  [31m3 checks failed:[0m
[2025-02-14T19:12:25.703+0000] {subprocess.py:106} INFO - [0m19:12:25  dbt looked for a profiles.yml file in /opt/***/dbt/profiles.yml, but did
[2025-02-14T19:12:25.713+0000] {subprocess.py:106} INFO - not find one. For more information on configuring your profile, consult the
[2025-02-14T19:12:25.714+0000] {subprocess.py:106} INFO - documentation:
[2025-02-14T19:12:25.716+0000] {subprocess.py:106} INFO - 
[2025-02-14T19:12:25.717+0000] {subprocess.py:106} INFO - https://docs.getdbt.com/docs/configure-your-profile
[2025-02-14T19:12:25.718+0000] {subprocess.py:106} INFO - 
[2025-02-14T19:12:25.718+0000] {subprocess.py:106} INFO - 
[2025-02-14T19:12:25.721+0000] {subprocess.py:106} INFO - [0m19:12:25  Project loading failed for the following reason:
[2025-02-14T19:12:25.728+0000] {subprocess.py:106} INFO -  project path </tmp/***tmpjtdxmxq1/dbt_project.yml> not found
[2025-02-14T19:12:25.731+0000] {subprocess.py:106} INFO - 
[2025-02-14T19:12:25.733+0000] {subprocess.py:106} INFO - [0m19:12:25  Error from git --help: User does not have permissions for this command: "git"
[2025-02-14T19:12:25.734+0000] {subprocess.py:106} INFO - 
[2025-02-14T19:12:27.180+0000] {subprocess.py:110} INFO - Command exited with return code 1
[2025-02-14T19:12:27.212+0000] {taskinstance.py:3313} ERROR - Task failed with exception
Traceback (most recent call last):
  File "/home/airflow/.local/lib/python3.12/site-packages/airflow/models/taskinstance.py", line 768, in _execute_task
    result = _execute_callable(context=context, **execute_callable_kwargs)
             ^^^^^^^^^^^^^^^^^^^^^^^^^^^^^^^^^^^^^^^^^^^^^^^^^^^^^^^^^^^^^
  File "/home/airflow/.local/lib/python3.12/site-packages/airflow/models/taskinstance.py", line 734, in _execute_callable
    return ExecutionCallableRunner(
           ^^^^^^^^^^^^^^^^^^^^^^^^
  File "/home/airflow/.local/lib/python3.12/site-packages/airflow/utils/operator_helpers.py", line 252, in run
    return self.func(*args, **kwargs)
           ^^^^^^^^^^^^^^^^^^^^^^^^^^
  File "/home/airflow/.local/lib/python3.12/site-packages/airflow/models/baseoperator.py", line 424, in wrapper
    return func(self, *args, **kwargs)
           ^^^^^^^^^^^^^^^^^^^^^^^^^^^
  File "/home/airflow/.local/lib/python3.12/site-packages/airflow/operators/bash.py", line 276, in execute
    raise AirflowException(
airflow.exceptions.AirflowException: Bash command failed. The command returned a non-zero exit code 1.
[2025-02-14T19:12:27.245+0000] {taskinstance.py:1226} INFO - Marking task as UP_FOR_RETRY. dag_id=dbt_snowflake_dag, task_id=dbt_debug, run_id=scheduled__2025-02-13T00:00:00+00:00, execution_date=20250213T000000, start_date=20250214T191213, end_date=20250214T191227
[2025-02-14T19:12:27.333+0000] {taskinstance.py:341} INFO - ::group::Post task execution logs
[2025-02-14T19:12:27.336+0000] {standard_task_runner.py:124} ERROR - Failed to execute job 146 for task dbt_debug (Bash command failed. The command returned a non-zero exit code 1.; 82)
Traceback (most recent call last):
  File "/home/airflow/.local/lib/python3.12/site-packages/airflow/task/task_runner/standard_task_runner.py", line 117, in _start_by_fork
    ret = args.func(args, dag=self.dag)
          ^^^^^^^^^^^^^^^^^^^^^^^^^^^^^
  File "/home/airflow/.local/lib/python3.12/site-packages/airflow/cli/cli_config.py", line 49, in command
    return func(*args, **kwargs)
           ^^^^^^^^^^^^^^^^^^^^^
  File "/home/airflow/.local/lib/python3.12/site-packages/airflow/utils/cli.py", line 116, in wrapper
    return f(*args, **kwargs)
           ^^^^^^^^^^^^^^^^^^
  File "/home/airflow/.local/lib/python3.12/site-packages/airflow/cli/commands/task_command.py", line 483, in task_run
    task_return_code = _run_task_by_selected_method(args, _dag, ti)
                       ^^^^^^^^^^^^^^^^^^^^^^^^^^^^^^^^^^^^^^^^^^^^
  File "/home/airflow/.local/lib/python3.12/site-packages/airflow/cli/commands/task_command.py", line 256, in _run_task_by_selected_method
    return _run_raw_task(args, ti)
           ^^^^^^^^^^^^^^^^^^^^^^^
  File "/home/airflow/.local/lib/python3.12/site-packages/airflow/cli/commands/task_command.py", line 341, in _run_raw_task
    return ti._run_raw_task(
           ^^^^^^^^^^^^^^^^^
  File "/home/airflow/.local/lib/python3.12/site-packages/airflow/utils/session.py", line 97, in wrapper
    return func(*args, session=session, **kwargs)
           ^^^^^^^^^^^^^^^^^^^^^^^^^^^^^^^^^^^^^^
  File "/home/airflow/.local/lib/python3.12/site-packages/airflow/models/taskinstance.py", line 3006, in _run_raw_task
    return _run_raw_task(
           ^^^^^^^^^^^^^^
  File "/home/airflow/.local/lib/python3.12/site-packages/airflow/models/taskinstance.py", line 274, in _run_raw_task
    TaskInstance._execute_task_with_callbacks(
  File "/home/airflow/.local/lib/python3.12/site-packages/airflow/models/taskinstance.py", line 3161, in _execute_task_with_callbacks
    result = self._execute_task(context, task_orig)
             ^^^^^^^^^^^^^^^^^^^^^^^^^^^^^^^^^^^^^^
  File "/home/airflow/.local/lib/python3.12/site-packages/airflow/models/taskinstance.py", line 3185, in _execute_task
    return _execute_task(self, context, task_orig)
           ^^^^^^^^^^^^^^^^^^^^^^^^^^^^^^^^^^^^^^^
  File "/home/airflow/.local/lib/python3.12/site-packages/airflow/models/taskinstance.py", line 768, in _execute_task
    result = _execute_callable(context=context, **execute_callable_kwargs)
             ^^^^^^^^^^^^^^^^^^^^^^^^^^^^^^^^^^^^^^^^^^^^^^^^^^^^^^^^^^^^^
  File "/home/airflow/.local/lib/python3.12/site-packages/airflow/models/taskinstance.py", line 734, in _execute_callable
    return ExecutionCallableRunner(
           ^^^^^^^^^^^^^^^^^^^^^^^^
  File "/home/airflow/.local/lib/python3.12/site-packages/airflow/utils/operator_helpers.py", line 252, in run
    return self.func(*args, **kwargs)
           ^^^^^^^^^^^^^^^^^^^^^^^^^^
  File "/home/airflow/.local/lib/python3.12/site-packages/airflow/models/baseoperator.py", line 424, in wrapper
    return func(self, *args, **kwargs)
           ^^^^^^^^^^^^^^^^^^^^^^^^^^^
  File "/home/airflow/.local/lib/python3.12/site-packages/airflow/operators/bash.py", line 276, in execute
    raise AirflowException(
airflow.exceptions.AirflowException: Bash command failed. The command returned a non-zero exit code 1.
[2025-02-14T19:12:27.378+0000] {local_task_job_runner.py:266} INFO - Task exited with return code 1
[2025-02-14T19:12:27.445+0000] {taskinstance.py:3901} INFO - 0 downstream tasks scheduled from follow-on schedule check
[2025-02-14T19:12:27.450+0000] {local_task_job_runner.py:245} INFO - ::endgroup::
