[2025-02-14T19:12:25.279+0000] {local_task_job_runner.py:123} INFO - ::group::Pre task execution logs
[2025-02-14T19:12:25.350+0000] {taskinstance.py:2614} INFO - Dependencies all met for dep_context=non-requeueable deps ti=<TaskInstance: dbt_snowflake_dag.dbt_debug manual__2025-02-14T19:12:10.246489+00:00 [queued]>
[2025-02-14T19:12:25.379+0000] {taskinstance.py:2614} INFO - Dependencies all met for dep_context=requeueable deps ti=<TaskInstance: dbt_snowflake_dag.dbt_debug manual__2025-02-14T19:12:10.246489+00:00 [queued]>
[2025-02-14T19:12:25.380+0000] {taskinstance.py:2867} INFO - Starting attempt 1 of 2
[2025-02-14T19:12:25.428+0000] {taskinstance.py:2890} INFO - Executing <Task(BashOperator): dbt_debug> on 2025-02-14 19:12:10.246489+00:00
[2025-02-14T19:12:25.448+0000] {warnings.py:112} WARNING - /home/***/.local/lib/python3.12/site-packages/***/task/task_runner/standard_task_runner.py:70: DeprecationWarning: This process (pid=84) is multi-threaded, use of fork() may lead to deadlocks in the child.
  pid = os.fork()

[2025-02-14T19:12:25.453+0000] {standard_task_runner.py:72} INFO - Started process 87 to run task
[2025-02-14T19:12:25.456+0000] {standard_task_runner.py:104} INFO - Running: ['***', 'tasks', 'run', 'dbt_snowflake_dag', 'dbt_debug', 'manual__2025-02-14T19:12:10.246489+00:00', '--job-id', '147', '--raw', '--subdir', 'DAGS_FOLDER/dbt-chck.py', '--cfg-path', '/tmp/tmp956psn7v']
[2025-02-14T19:12:25.463+0000] {standard_task_runner.py:105} INFO - Job 147: Subtask dbt_debug
[2025-02-14T19:12:25.624+0000] {task_command.py:467} INFO - Running <TaskInstance: dbt_snowflake_dag.dbt_debug manual__2025-02-14T19:12:10.246489+00:00 [running]> on host e9f6bf018f11
[2025-02-14T19:12:25.889+0000] {taskinstance.py:3134} INFO - Exporting env vars: AIRFLOW_CTX_DAG_OWNER='***' AIRFLOW_CTX_DAG_ID='dbt_snowflake_dag' AIRFLOW_CTX_TASK_ID='dbt_debug' AIRFLOW_CTX_EXECUTION_DATE='2025-02-14T19:12:10.246489+00:00' AIRFLOW_CTX_TRY_NUMBER='1' AIRFLOW_CTX_DAG_RUN_ID='manual__2025-02-14T19:12:10.246489+00:00'
[2025-02-14T19:12:25.893+0000] {taskinstance.py:732} INFO - ::endgroup::
[2025-02-14T19:12:25.935+0000] {subprocess.py:78} INFO - Tmp dir root location: /tmp
[2025-02-14T19:12:25.939+0000] {subprocess.py:88} INFO - Running command: ['/usr/bin/bash', '-c', 'dbt debug --profiles-dir /opt/***/dbt']
[2025-02-14T19:12:25.976+0000] {subprocess.py:99} INFO - Output:
[2025-02-14T19:12:34.425+0000] {subprocess.py:106} INFO - [0m19:12:34  Running with dbt=1.9.2
[2025-02-14T19:12:34.463+0000] {subprocess.py:106} INFO - [0m19:12:34  dbt version: 1.9.2
[2025-02-14T19:12:34.465+0000] {subprocess.py:106} INFO - [0m19:12:34  python version: 3.12.9
[2025-02-14T19:12:34.466+0000] {subprocess.py:106} INFO - [0m19:12:34  python path: /home/***/.local/bin/python
[2025-02-14T19:12:34.467+0000] {subprocess.py:106} INFO - [0m19:12:34  os info: Linux-5.15.133.1-microsoft-standard-WSL2-x86_64-with-glibc2.36
[2025-02-14T19:12:34.468+0000] {subprocess.py:106} INFO - [0m19:12:34  Using profiles dir at /opt/***/dbt
[2025-02-14T19:12:34.470+0000] {subprocess.py:106} INFO - [0m19:12:34  Using profiles.yml file at /opt/***/dbt/profiles.yml
[2025-02-14T19:12:34.471+0000] {subprocess.py:106} INFO - [0m19:12:34  Using dbt_project.yml file at /tmp/***tmpo2txkhxy/dbt_project.yml
[2025-02-14T19:12:34.472+0000] {subprocess.py:106} INFO - [0m19:12:34  Configuration:
[2025-02-14T19:12:34.480+0000] {subprocess.py:106} INFO - [0m19:12:34    profiles.yml file [[31mERROR not found[0m]
[2025-02-14T19:12:34.483+0000] {subprocess.py:106} INFO - [0m19:12:34    dbt_project.yml file [[31mERROR not found[0m]
[2025-02-14T19:12:34.484+0000] {subprocess.py:106} INFO - [0m19:12:34  Required dependencies:
[2025-02-14T19:12:34.485+0000] {subprocess.py:106} INFO - [0m19:12:34   - git [[31mERROR[0m]
[2025-02-14T19:12:34.486+0000] {subprocess.py:106} INFO - 
[2025-02-14T19:12:34.486+0000] {subprocess.py:106} INFO - [0m19:12:34  Connection test skipped since no profile was found
[2025-02-14T19:12:34.487+0000] {subprocess.py:106} INFO - [0m19:12:34  [31m3 checks failed:[0m
[2025-02-14T19:12:34.488+0000] {subprocess.py:106} INFO - [0m19:12:34  dbt looked for a profiles.yml file in /opt/***/dbt/profiles.yml, but did
[2025-02-14T19:12:34.488+0000] {subprocess.py:106} INFO - not find one. For more information on configuring your profile, consult the
[2025-02-14T19:12:34.489+0000] {subprocess.py:106} INFO - documentation:
[2025-02-14T19:12:34.489+0000] {subprocess.py:106} INFO - 
[2025-02-14T19:12:34.490+0000] {subprocess.py:106} INFO - https://docs.getdbt.com/docs/configure-your-profile
[2025-02-14T19:12:34.491+0000] {subprocess.py:106} INFO - 
[2025-02-14T19:12:34.491+0000] {subprocess.py:106} INFO - 
[2025-02-14T19:12:34.492+0000] {subprocess.py:106} INFO - [0m19:12:34  Project loading failed for the following reason:
[2025-02-14T19:12:34.493+0000] {subprocess.py:106} INFO -  project path </tmp/***tmpo2txkhxy/dbt_project.yml> not found
[2025-02-14T19:12:34.494+0000] {subprocess.py:106} INFO - 
[2025-02-14T19:12:34.495+0000] {subprocess.py:106} INFO - [0m19:12:34  Error from git --help: User does not have permissions for this command: "git"
[2025-02-14T19:12:34.496+0000] {subprocess.py:106} INFO - 
[2025-02-14T19:12:35.542+0000] {subprocess.py:110} INFO - Command exited with return code 1
[2025-02-14T19:12:35.569+0000] {taskinstance.py:3313} ERROR - Task failed with exception
Traceback (most recent call last):
  File "/home/airflow/.local/lib/python3.12/site-packages/airflow/models/taskinstance.py", line 768, in _execute_task
    result = _execute_callable(context=context, **execute_callable_kwargs)
             ^^^^^^^^^^^^^^^^^^^^^^^^^^^^^^^^^^^^^^^^^^^^^^^^^^^^^^^^^^^^^
  File "/home/airflow/.local/lib/python3.12/site-packages/airflow/models/taskinstance.py", line 734, in _execute_callable
    return ExecutionCallableRunner(
           ^^^^^^^^^^^^^^^^^^^^^^^^
  File "/home/airflow/.local/lib/python3.12/site-packages/airflow/utils/operator_helpers.py", line 252, in run
    return self.func(*args, **kwargs)
           ^^^^^^^^^^^^^^^^^^^^^^^^^^
  File "/home/airflow/.local/lib/python3.12/site-packages/airflow/models/baseoperator.py", line 424, in wrapper
    return func(self, *args, **kwargs)
           ^^^^^^^^^^^^^^^^^^^^^^^^^^^
  File "/home/airflow/.local/lib/python3.12/site-packages/airflow/operators/bash.py", line 276, in execute
    raise AirflowException(
airflow.exceptions.AirflowException: Bash command failed. The command returned a non-zero exit code 1.
[2025-02-14T19:12:35.605+0000] {taskinstance.py:1226} INFO - Marking task as UP_FOR_RETRY. dag_id=dbt_snowflake_dag, task_id=dbt_debug, run_id=manual__2025-02-14T19:12:10.246489+00:00, execution_date=20250214T191210, start_date=20250214T191225, end_date=20250214T191235
[2025-02-14T19:12:35.726+0000] {taskinstance.py:341} INFO - ::group::Post task execution logs
[2025-02-14T19:12:35.728+0000] {standard_task_runner.py:124} ERROR - Failed to execute job 147 for task dbt_debug (Bash command failed. The command returned a non-zero exit code 1.; 87)
Traceback (most recent call last):
  File "/home/airflow/.local/lib/python3.12/site-packages/airflow/task/task_runner/standard_task_runner.py", line 117, in _start_by_fork
    ret = args.func(args, dag=self.dag)
          ^^^^^^^^^^^^^^^^^^^^^^^^^^^^^
  File "/home/airflow/.local/lib/python3.12/site-packages/airflow/cli/cli_config.py", line 49, in command
    return func(*args, **kwargs)
           ^^^^^^^^^^^^^^^^^^^^^
  File "/home/airflow/.local/lib/python3.12/site-packages/airflow/utils/cli.py", line 116, in wrapper
    return f(*args, **kwargs)
           ^^^^^^^^^^^^^^^^^^
  File "/home/airflow/.local/lib/python3.12/site-packages/airflow/cli/commands/task_command.py", line 483, in task_run
    task_return_code = _run_task_by_selected_method(args, _dag, ti)
                       ^^^^^^^^^^^^^^^^^^^^^^^^^^^^^^^^^^^^^^^^^^^^
  File "/home/airflow/.local/lib/python3.12/site-packages/airflow/cli/commands/task_command.py", line 256, in _run_task_by_selected_method
    return _run_raw_task(args, ti)
           ^^^^^^^^^^^^^^^^^^^^^^^
  File "/home/airflow/.local/lib/python3.12/site-packages/airflow/cli/commands/task_command.py", line 341, in _run_raw_task
    return ti._run_raw_task(
           ^^^^^^^^^^^^^^^^^
  File "/home/airflow/.local/lib/python3.12/site-packages/airflow/utils/session.py", line 97, in wrapper
    return func(*args, session=session, **kwargs)
           ^^^^^^^^^^^^^^^^^^^^^^^^^^^^^^^^^^^^^^
  File "/home/airflow/.local/lib/python3.12/site-packages/airflow/models/taskinstance.py", line 3006, in _run_raw_task
    return _run_raw_task(
           ^^^^^^^^^^^^^^
  File "/home/airflow/.local/lib/python3.12/site-packages/airflow/models/taskinstance.py", line 274, in _run_raw_task
    TaskInstance._execute_task_with_callbacks(
  File "/home/airflow/.local/lib/python3.12/site-packages/airflow/models/taskinstance.py", line 3161, in _execute_task_with_callbacks
    result = self._execute_task(context, task_orig)
             ^^^^^^^^^^^^^^^^^^^^^^^^^^^^^^^^^^^^^^
  File "/home/airflow/.local/lib/python3.12/site-packages/airflow/models/taskinstance.py", line 3185, in _execute_task
    return _execute_task(self, context, task_orig)
           ^^^^^^^^^^^^^^^^^^^^^^^^^^^^^^^^^^^^^^^
  File "/home/airflow/.local/lib/python3.12/site-packages/airflow/models/taskinstance.py", line 768, in _execute_task
    result = _execute_callable(context=context, **execute_callable_kwargs)
             ^^^^^^^^^^^^^^^^^^^^^^^^^^^^^^^^^^^^^^^^^^^^^^^^^^^^^^^^^^^^^
  File "/home/airflow/.local/lib/python3.12/site-packages/airflow/models/taskinstance.py", line 734, in _execute_callable
    return ExecutionCallableRunner(
           ^^^^^^^^^^^^^^^^^^^^^^^^
  File "/home/airflow/.local/lib/python3.12/site-packages/airflow/utils/operator_helpers.py", line 252, in run
    return self.func(*args, **kwargs)
           ^^^^^^^^^^^^^^^^^^^^^^^^^^
  File "/home/airflow/.local/lib/python3.12/site-packages/airflow/models/baseoperator.py", line 424, in wrapper
    return func(self, *args, **kwargs)
           ^^^^^^^^^^^^^^^^^^^^^^^^^^^
  File "/home/airflow/.local/lib/python3.12/site-packages/airflow/operators/bash.py", line 276, in execute
    raise AirflowException(
airflow.exceptions.AirflowException: Bash command failed. The command returned a non-zero exit code 1.
[2025-02-14T19:12:35.786+0000] {local_task_job_runner.py:266} INFO - Task exited with return code 1
[2025-02-14T19:12:35.849+0000] {taskinstance.py:3901} INFO - 0 downstream tasks scheduled from follow-on schedule check
[2025-02-14T19:12:35.863+0000] {local_task_job_runner.py:245} INFO - ::endgroup::
