[2025-02-14T20:05:25.701+0000] {local_task_job_runner.py:123} INFO - ::group::Pre task execution logs
[2025-02-14T20:05:25.727+0000] {taskinstance.py:2614} INFO - Dependencies all met for dep_context=non-requeueable deps ti=<TaskInstance: dbt-etl-dag.decide_next_step scheduled__2025-02-13T00:00:00+00:00 [queued]>
[2025-02-14T20:05:25.736+0000] {taskinstance.py:2614} INFO - Dependencies all met for dep_context=requeueable deps ti=<TaskInstance: dbt-etl-dag.decide_next_step scheduled__2025-02-13T00:00:00+00:00 [queued]>
[2025-02-14T20:05:25.737+0000] {taskinstance.py:2867} INFO - Starting attempt 1 of 1
[2025-02-14T20:05:25.757+0000] {taskinstance.py:2890} INFO - Executing <Task(BranchPythonOperator): decide_next_step> on 2025-02-13 00:00:00+00:00
[2025-02-14T20:05:25.768+0000] {warnings.py:112} WARNING - /home/***/.local/lib/python3.12/site-packages/***/task/task_runner/standard_task_runner.py:70: DeprecationWarning: This process (pid=122) is multi-threaded, use of fork() may lead to deadlocks in the child.
  pid = os.fork()

[2025-02-14T20:05:25.769+0000] {standard_task_runner.py:72} INFO - Started process 124 to run task
[2025-02-14T20:05:25.770+0000] {standard_task_runner.py:104} INFO - Running: ['***', 'tasks', 'run', 'dbt-etl-dag', 'decide_next_step', 'scheduled__2025-02-13T00:00:00+00:00', '--job-id', '180', '--raw', '--subdir', 'DAGS_FOLDER/dbt-etl.py', '--cfg-path', '/tmp/tmpms378gxn']
[2025-02-14T20:05:25.774+0000] {standard_task_runner.py:105} INFO - Job 180: Subtask decide_next_step
[2025-02-14T20:05:25.826+0000] {task_command.py:467} INFO - Running <TaskInstance: dbt-etl-dag.decide_next_step scheduled__2025-02-13T00:00:00+00:00 [running]> on host aff10611ebf2
[2025-02-14T20:05:25.917+0000] {taskinstance.py:3134} INFO - Exporting env vars: AIRFLOW_CTX_DAG_OWNER='***' AIRFLOW_CTX_DAG_ID='dbt-etl-dag' AIRFLOW_CTX_TASK_ID='decide_next_step' AIRFLOW_CTX_EXECUTION_DATE='2025-02-13T00:00:00+00:00' AIRFLOW_CTX_TRY_NUMBER='1' AIRFLOW_CTX_DAG_RUN_ID='scheduled__2025-02-13T00:00:00+00:00'
[2025-02-14T20:05:25.919+0000] {taskinstance.py:732} INFO - ::endgroup::
[2025-02-14T20:05:25.936+0000] {baseoperator.py:423} WARNING - BranchPythonOperator.execute cannot be called outside TaskInstance!
[2025-02-14T20:05:25.945+0000] {logging_mixin.py:190} INFO - here is result
[2025-02-14T20:05:25.946+0000] {logging_mixin.py:190} INFO - [{'COUNT(*)': 4}]
[2025-02-14T20:05:25.946+0000] {python.py:240} INFO - Done. Returned value was: proceed_with_next_task
[2025-02-14T20:05:25.947+0000] {branch.py:38} INFO - Branch into proceed_with_next_task
[2025-02-14T20:05:25.947+0000] {skipmixin.py:233} INFO - Following branch ('proceed_with_next_task',)
[2025-02-14T20:05:25.959+0000] {skipmixin.py:281} INFO - Skipping tasks [('no_required_tables_found', -1)]
[2025-02-14T20:05:25.992+0000] {taskinstance.py:341} INFO - ::group::Post task execution logs
[2025-02-14T20:05:25.993+0000] {taskinstance.py:353} INFO - Marking task as SUCCESS. dag_id=dbt-etl-dag, task_id=decide_next_step, run_id=scheduled__2025-02-13T00:00:00+00:00, execution_date=20250213T000000, start_date=20250214T200525, end_date=20250214T200525
[2025-02-14T20:05:26.065+0000] {local_task_job_runner.py:266} INFO - Task exited with return code 0
[2025-02-14T20:05:26.124+0000] {taskinstance.py:3901} INFO - 1 downstream tasks scheduled from follow-on schedule check
[2025-02-14T20:05:26.135+0000] {local_task_job_runner.py:245} INFO - ::endgroup::
